ERROR:django.request:Internal Server Error: /
Traceback (most recent call last):
  File "/home/velavok/ML/DEEPLOM/WEB/lib/python3.6/site-packages/django/core/handlers/exception.py", line 34, in inner
    response = get_response(request)
  File "/home/velavok/ML/DEEPLOM/WEB/lib/python3.6/site-packages/django/core/handlers/base.py", line 115, in _get_response
    response = self.process_exception_by_middleware(e, request)
  File "/home/velavok/ML/DEEPLOM/WEB/lib/python3.6/site-packages/django/core/handlers/base.py", line 113, in _get_response
    response = wrapped_callback(request, *callback_args, **callback_kwargs)
  File "/home/velavok/ML/DEEPLOM/WEB/Look4Face/Main/views.py", line 79, in main
    D, I = search(img) # distances and indexes
  File "/home/velavok/ML/DEEPLOM/WEB/Look4Face/Main/views.py", line 97, in search
    query = np.array(extract_one_embedding(img, backbone, pth)).astype('float32').reshape(1,-1)
  File "/home/velavok/ML/DEEPLOM/WEB/Look4Face/util/extract_features.py", line 70, in extract_one_embedding
    backbone.load_state_dict(torch.load(model_root))
  File "/home/velavok/ML/DEEPLOM/WEB/lib/python3.6/site-packages/torch/serialization.py", line 366, in load
    f = open(f, 'rb')
FileNotFoundError: [Errno 2] No such file or directory: '/home/velavok/ML/DEEPLOM/WEB/Look4Face/backbone/Backbone.pth'
